<?xml version="1.0"?>
<robot name="real_world_pendulum">

  <link name="world"/>

  <link name="rail">
    <visual>
      <geometry><box size="0.3 0.01 0.01"/></geometry>
      <material name="grey"><color rgba="0.5 0.5 0.5 1"/></material>
    </visual>
    <collision>
      <geometry><box size="0.3 0.01 0.01"/></geometry>
    </collision>
    <inertial>
      <mass value="1.0"/>
      <inertia ixx="0.001" ixy="0" ixz="0" iyy="0.001" iyz="0" izz="0.001"/>
    </inertial>
  </link>

  <joint name="world_to_rail" type="fixed">
    <parent link="world"/>
    <child link="rail"/>
    <origin xyz="0 0 0"/>
  </joint>

  <link name="cart">
    <visual>
      <geometry><box size="0.05 0.05 0.05"/></geometry>
      <material name="blue"><color rgba="0 0 1 1"/></material>
    </visual>
    <collision>
      <geometry><box size="0.05 0.05 0.05"/></geometry>
    </collision>
    <inertial>
      <mass value="0.5"/>
      <inertia ixx="0.0002" ixy="0" ixz="0" iyy="0.0002" iyz="0" izz="0.0002"/>
    </inertial>
  </link>

  <joint name="rail_to_cart" type="prismatic">
    <parent link="rail"/>
    <child link="cart"/>
    <origin xyz="0 0 0.03"/> <axis xyz="1 0 0"/>
    <limit lower="-0.125" upper="0.125" effort="10.0" velocity="1.0"/>
  </joint>

  <link name="pole">
    <visual>
      <origin xyz="0 0 0.125" rpy="0 0 0"/>
      <geometry><cylinder radius="0.01" length="0.25"/></geometry>
      <material name="red"><color rgba="1 0 0 1"/></material>
    </visual>
    <collision>
      <origin xyz="0 0 0.125" rpy="0 0 0"/>
      <geometry><cylinder radius="0.01" length="0.25"/></geometry>
    </collision>
    <inertial>
      <origin xyz="0 0 0.125"/>
      <mass value="0.1"/>
      <inertia ixx="0.0005" ixy="0" ixz="0" iyy="0.0005" iyz="0" izz="0.00001"/>
    </inertial>
  </link>

  <joint name="cart_to_pole" type="continuous">
    <parent link="cart"/>
    <child link="pole"/>
    <origin xyz="0 0 0.025"/> <axis xyz="0 1 0"/>
  </joint>

</robot>